Workbook

Sheet README
A1: Grad Program ROI — hand-check test cases (spec v0.2, §5 model)
A3: Purpose: five worked cases whose outputs become the unit tests for the app's model module.
A4: Each case sheet has: INPUTS (yellow cells, blue text — the only cells to edit), DERIVED values, a 20-row annual table, and OUTPUTS.
A5: All inputs are hypothetical except Case 3's S1 = 73,268, which is the College Scorecard 1-year median for Cal Poly CIP 5213 master's (API, Sept 9, 2026).
A7: Model, per year k (after-tax cash):
A8: CF_A(k) = S0·(1+g_work)^(k−1)·(1−t)
A9: CF_B(k) = −C_sch·sf(k) + S1·(1+g_grad)^exp(k)·(1−t)·wf(k) − P·lf(k)
A10: C_sch = (T−Sch−B)/L + Living − PT·(1−t) cash cost per school-year (borrowed money excluded; it returns as P)
A11: sf(k) = fraction of year k spent in school = clamp(L−(k−1), 0, 1)
A12: ts = L + gap/12 = when the new salary starts; wf(k) = fraction of year k after ts = clamp(k−ts, 0, 1)
A13: exp(k) = k − kf where kf = FLOOR(ts)+1 is the first working year (so the first working year gets exponent 0)
A14: lf(k) = fraction of year k inside the loan term [L, L+N]; P = B·r/(1−(1+r)^−N)
... A23: Sheet Build4_StudyScenarios: hand-worked cases for part-time study, tuition reimbursement and the three scenarios (src/lib/scenarios.test.ts), plus the payback-rule case (src/lib/model.test.ts).

Sheet Summary
A1: Case | B1: Payback year | C1: NPV ($) | D1: Breakeven S1* ($) | E1: Scorecard/entered S1 ($) | F1: Expected behaviour
A2: 1. Cheap program, big salary jump | B2: =Case1_CheapBigJump!C51 -> 4 | C2: =Case1_CheapBigJump!C52 -> 129985.68 | D2: =Case1_CheapBigJump!C54 -> 72292.12 | E2: =Case1_CheapBigJump!$C$16 -> 95000 | F2: Pays back in year 4; large positive NPV; breakeven S1 well below 95k
A3: 2. Expensive program, small salary jump | B3: =Case2_ExpensiveSmallJump!C51 -> Not within horizon | C3: =Case2_ExpensiveSmallJump!C52 -> -177085.59 | D3: =Case2_ExpensiveSmallJump!C54 -> 116500.9 | E3: =Case2_ExpensiveSmallJump!$C$16 -> 80000 | F3: Does not pay back within 10 years; NPV negative; breakeven S1 well above 80k
A4: 3. Ten-month program (MSBA-like), Scorecard salary | B4: =Case3_MSBA_Fractional!C51 -> Not within horizon | C4: =Case3_MSBA_Fractional!C52 -> -34721.133 | D4: =Case3_MSBA_Fractional!C54 -> 79213.501 | E4: =Case3_MSBA_Fractional!$C$16 -> 73268 | F4: Fractional year and mid-year salary start prorate correctly. With S0 = 65k, the Scorecard 1-yr median (73k) is not enough: no payback in 10 yrs, breakeven S1 ≈ 79k
A5: 4. No borrowing (paid from savings) | B5: =Case4_NoLoans!C51 -> 6 | C5: =Case4_NoLoans!C52 -> 49433.126 | D5: =Case4_NoLoans!C54 -> 66364.268 | E5: =Case4_NoLoans!$C$16 -> 75000 | F5: Loan payment P = 0; full net tuition (20k) hits year 1; pays back around year 6
A6: 5. High salary already, program never pays off | B6: =Case5_NeverPaysOff!C51 -> Not within horizon | C6: =Case5_NeverPaysOff!C52 -> -222750.35 | D6: =Case5_NeverPaysOff!C54 -> 137913.32 | E6: =Case5_NeverPaysOff!$C$16 -> 92000 | F6: Never pays back; NPV strongly negative; breakeven S1 far above 92k
A8: Green = linked from the case sheets. Change inputs on a case sheet, not here.

Sheet Build4_StudyScenarios
A1: Build 4 — part-time study, tuition reimbursement, scenarios
A2: Hand-worked cases behind src/lib/scenarios.test.ts (12) and the payback-rule case in src/lib/model.test.ts. None changes the model: each is a transform on the model's own inputs, then the §5 model runs as on the case sheets.
A3: Part-time: L = part-time length, PT = pay kept. Reimbursement R per school-year: Sch += MIN(R·L, MAX(T−Sch,0)); then B is capped at MAX(T−Sch,0) when reimbursement is used. Scenarios (spec A2): pessimistic S1 = S0 + uplift·½, gap = MAX(gap, 9), g_grad = MIN(g_grad, g_work); optimistic S1 = S0 + uplift·1.25, gap = 0. Each takes the worse/better of its rule and the entered value, so they never cross.
A5: SHARED INPUTS (cases 1–7; blue = hardcoded)
A6: Current salary S0 | C6: 60000 | E6: Keep working, after tax, per year: | H6: =$C$6*(1-$C$8) -> 45000
A7: Raise rate g_work | C7: 0 | E7: After the program, after tax, per year: | H7: =$C$15*(1-$C$8) -> 60000
A8: Tax rate t | C8: 0.25
A9: Discount rate d | C9: 0
A10: Horizon H | C10: 5
A11: Full-time length L | C11: 1
A12: Tuition T | C12: 20000
A13: Living | C13: 0
A14: Job search gap (months) | C14: 0
A15: Starting salary S1 | C15: 80000
A16: Raise rate after g_grad | C16: 0
A18: A. PART-TIME AND REIMBURSEMENT (no raises, d = 0, no loan unless set, no job search)
A19: Case | B19: Part-time? | C19: Part-time length | D19: Pay kept /yr | E19: Reimb. /yr | F19: Sch | G19: B | H19: L used | I19: PT used | J19: Reimb. total | K19: Sch used | L19: B used | M19: C_sch | N19: Hand-worked expected | O19: Test
A20: 1. Full-time reference | B20: No | C20: 0 | D20: 0 | E20: 0 | F20: 0 | G20: 0 | H20: =IF(B20="Yes",C20,$C$11) -> 1 | I20: =IF(B20="Yes",D20,0) -> 0 | J20: =MIN(MAX(E20,0)*H20,MAX($C$12-F20,0)) -> 0 | K20: =F20+J20 -> 0 | L20: =IF(AND(J20>0,G20>MAX($C$12-K20,0)),MAX($C$12-K20,0),G20) -> 0 | M20: =($C$12-K20-L20)/H20+$C$13-I20*(1-$C$8) -> 20000 | N20: C_sch 20,000. CumDiff −65,000, −50,000, −35,000, −20,000, −5,000 → no payback. | O20: full-time reference (no options)
A21: 2. Part-time lengthens and keeps pay | B21: Yes | C21: 2 | D21: 60000 | E21: 0 | F21: 0 | G21: 0 | H21: =IF(B21="Yes",C21,$C$11) -> 2 | I21: =IF(B21="Yes",D21,0) -> 60000 | J21: =MIN(MAX(E21,0)*H21,MAX($C$12-F21,0)) -> 0 | K21: =F21+J21 -> 0 | L21: =IF(AND(J21>0,G21>MAX($C$12-K21,0)),MAX($C$12-K21,0),G21) -> 0 | M21: =($C$12-K21-L21)/H21+$C$13-I21*(1-$C$8) -> -35000 | N21: L = 2, PT = 60,000. | O21: part-time study › lengthens the program and keeps the pay
A22: 3. Part-time, 2 years keeping $60k | B22: Yes | C22: 2 | D22: 60000 | E22: 0 | F22: 0 | G22: 0 | H22: =IF(B22="Yes",C22,$C$11) -> 2 | I22: =IF(B22="Yes",D22,0) -> 60000 | J22: =MIN(MAX(E22,0)*H22,MAX($C$12-F22,0)) -> 0 | K22: =F22+J22 -> 0 | L22: =IF(AND(J22>0,G22>MAX($C$12-K22,0)),MAX($C$12-K22,0),G22) -> 0 | M22: =($C$12-K22-L22)/H22+$C$13-I22*(1-$C$8) -> -35000 | N22: C_sch = 10,000 − 45,000 = −35,000; years 1–2 Diff −10,000; years 3–5 +15,000. CumDiff −10,000, −20,000, −5,000, 10,000, 25,000 → payback 4; NPV 25,000; Σm 2.25; S1* = (80,000·2.25 − 25,000)/2.25 = 68,888.89. | O22: part-time study › matches the hand calculation
A23: 4. Reimbursement $5,250/yr | B23: No | C23: 0 | D23: 0 | E23: 5250 | F23: 0 | G23: 0 | H23: =IF(B23="Yes",C23,$C$11) -> 1 | I23: =IF(B23="Yes",D23,0) -> 0 | J23: =MIN(MAX(E23,0)*H23,MAX($C$12-F23,0)) -> 5250 | K23: =F23+J23 -> 5250 | L23: =IF(AND(J23>0,G23>MAX($C$12-K23,0)),MAX($C$12-K23,0),G23) -> 0 | M23: =($C$12-K23-L23)/H23+$C$13-I23*(1-$C$8) -> 14750 | N23: Sch 5,250; C_sch 14,750; year 1 CumDiff −59,750; CumDiff(5) = 250 → payback 5. | O23: tuition reimbursement › cuts each school-year's cost
A24: 5. Reimbursement capped at tuition | B24: No | C24: 0 | D24: 0 | E24: 30000 | F24: 5000 | G24: 0 | H24: =IF(B24="Yes",C24,$C$11) -> 1 | I24: =IF(B24="Yes",D24,0) -> 0 | J24: =MIN(MAX(E24,0)*H24,MAX($C$12-F24,0)) -> 15000 | K24: =F24+J24 -> 20000 | L24: =IF(AND(J24>0,G24>MAX($C$12-K24,0)),MAX($C$12-K24,0),G24) -> 0 | M24: =($C$12-K24-L24)/H24+$C$13-I24*(1-$C$8) -> 0 | N24: Reimb. total = MIN(30,000, 20,000 − 5,000) = 15,000; C_sch 0. | O24: tuition reimbursement › never pays more than tuition
A25: 6. Borrowing capped at what's left | B25: No | C25: 0 | D25: 0 | E25: 5250 | F25: 0 | G25: 20000 | H25: =IF(B25="Yes",C25,$C$11) -> 1 | I25: =IF(B25="Yes",D25,0) -> 0 | J25: =MIN(MAX(E25,0)*H25,MAX($C$12-F25,0)) -> 5250 | K25: =F25+J25 -> 5250 | L25: =IF(AND(J25>0,G25>MAX($C$12-K25,0)),MAX($C$12-K25,0),G25) -> 14750 | M25: =($C$12-K25-L25)/H25+$C$13-I25*(1-$C$8) -> 0 | N25: Left to pay 20,000 − 5,250 = 14,750 → B 14,750; C_sch 0. | O25: tuition reimbursement › caps borrowing
A26: 7. Part-time + reimbursement | B26: Yes | C26: 2 | D26: 60000 | E26: 5250 | F26: 0 | G26: 0 | H26: =IF(B26="Yes",C26,$C$11) -> 2 | I26: =IF(B26="Yes",D26,0) -> 60000 | J26: =MIN(MAX(E26,0)*H26,MAX($C$12-F26,0)) -> 10500 | K26: =F26+J26 -> 10500 | L26: =IF(AND(J26>0,G26>MAX($C$12-K26,0)),MAX($C$12-K26,0),G26) -> 0 | M26: =($C$12-K26-L26)/H26+$C$13-I26*(1-$C$8) -> -40250 | N26: Sch 10,500; C_sch = 4,750 − 45,000 = −40,250; years 1–2 Diff −4,750. CumDiff −4,750, −9,500, 5,500, 20,500, 35,500 → payback 3. | O26: tuition reimbursement › combines with part-time
A29: B. SCENARIOS (spec A2), from the entered values
A30: Case | B30: S0 | C30: S1 entered | D30: gap entered | E30: g_work | F30: g_grad entered | G30: Pess. S1 | H30: Pess. gap | I30: Pess. g_grad | J30: Opt. S1 | K30: Opt. gap | L30: Opt. g_grad | N30: Hand-worked expected | O30: Test
A31: 8. Base is the inputs as entered | B31: 60000 | C31: 80000 | D31: 3 | E31: 0.03 | F31: 0.04 | G31: =MIN(B31+(C31-B31)*0.5,B31+(C31-B31)*1.25) -> 70000 | H31: =MAX(D31,9) -> 9 | I31: =MIN(F31,E31) -> 0.03 | J31: =MAX(B31+(C31-B31)*0.5,B31+(C31-B31)*1.25) -> 85000 | K31: 0 | L31: =F31 -> 0.04 | N31: Base = entered: S1 80,000, gap 3, g_grad 4%. | O31: scenarios › base is the inputs as entered
A32: 9. Pessimistic | B32: 60000 | C32: 80000 | D32: 3 | E32: 0.03 | F32: 0.04 | G32: =MIN(B32+(C32-B32)*0.5,B32+(C32-B32)*1.25) -> 70000 | H32: =MAX(D32,9) -> 9 | I32: =MIN(F32,E32) -> 0.03 | J32: =MAX(B32+(C32-B32)*0.5,B32+(C32-B32)*1.25) -> 85000 | K32: 0 | L32: =F32 -> 0.04 | N32: S1 = 60,000 + 20,000/2 = 70,000; gap 9; g_grad 3%. | O32: scenarios › pessimistic halves the uplift
A33: 10. Optimistic | B33: 60000 | C33: 80000 | D33: 3 | E33: 0.03 | F33: 0.04 | G33: =MIN(B33+(C33-B33)*0.5,B33+(C33-B33)*1.25) -> 70000 | H33: =MAX(D33,9) -> 9 | I33: =MIN(F33,E33) -> 0.03 | J33: =MAX(B33+(C33-B33)*0.5,B33+(C33-B33)*1.25) -> 85000 | K33: 0 | L33: =F33 -> 0.04 | N33: S1 = 60,000 + 20,000·1.25 = 85,000; gap 0; g_grad 4%. | O33: scenarios › optimistic adds a quarter to the uplift
A34: 11. Pay cut: pessimistic never better than base | B34: 60000 | C34: 50000 | D34: 12 | E34: 0.03 | F34: 0.02 | G34: =MIN(B34+(C34-B34)*0.5,B34+(C34-B34)*1.25) -> 47500 | H34: =MAX(D34,9) -> 12 | I34: =MIN(F34,E34) -> 0.02 | J34: =MAX(B34+(C34-B34)*0.5,B34+(C34-B34)*1.25) -> 55000 | K34: 0 | L34: =F34 -> 0.02 | N34: Uplift −10,000: pessimistic S1 47,500 (the bigger cut), optimistic 55,000; pessimistic keeps gap 12 and g_grad 2%. | O34: scenarios › never makes pessimistic better than base
A35: 12. Outcomes ordered (d 5%, H 10, L 1, T 20,000, B 0) | B35: 60000 | C35: 80000 | D35: 3 | E35: 0.03 | F35: 0.04 | G35: =MIN(B35+(C35-B35)*0.5,B35+(C35-B35)*1.25) -> 70000 | H35: =MAX(D35,9) -> 9 | I35: =MIN(F35,E35) -> 0.03 | J35: =MAX(B35+(C35-B35)*0.5,B35+(C35-B35)*1.25) -> 85000 | K35: 0 | L35: =F35 -> 0.04 | N35: Model NPVs: pessimistic −51,074.80 < base 45,250.91 < optimistic 88,327.97. The chart band contains the base line every year. | O35: scenarios › orders the outcomes and bands the base line
A38: C. PAYBACK RULE (src/lib/model.test.ts)
A39: Case | B39: S0 | C39: g_work | D39: t | E39: L (part-time) | F39: T | G39: B | H39: PT | I39: C_sch | J39: Year 1 CumDiff | K39: Year 2 CumDiff | L39: Year 3 CumDiff | M39: Payback | N39: Hand-worked expected | O39: Test
A40: 13. Part-time: year 1 touches 0, then goes negative | B40: 60000 | C40: 0.03 | D40: 0.25 | E40: 4 | F40: 40000 | G40: 40000 | H40: 60000 | I40: =(F40-G40)/E40-H40*(1-D40) -> -45000 | J40: =-I40-B40*(1-D40) -> 0 | K40: =J40+(-I40-B40*(1+C40)*(1-D40)) -> -1350 | L40: =K40+(-I40-B40*(1+C40)^2*(1-D40)) -> -4090.5 | M40: 7 | N40: Other inputs: d 5%, H 10, Sch 0, Living 0, gap 3, S1 85,000, g_grad 4%, r 8%, N 10. CumDiff 0, −1,350, −4,090.50, … stays ≥ 0 only from year 7. Old rule: year 1; new rule: year 7. | O40: payback › does not count a year-1 touch of zero

Sheet Case1_CheapBigJump
A1: 1. Cheap program, big salary jump
A2: Expected behaviour: Pays back in year 4; large positive NPV; breakeven S1 well below 95k
A4: INPUTS (blue = hardcoded; edit these) | B4: Symbol
A5: Current salary (pre-tax, $/yr) | B5: S0 | C5: 60000
A6: Raise rate if you keep working | B6: g_work | C6: 0.03
A7: Effective tax rate (flat) | B7: t | C7: 0.25
A8: Discount rate | B8: d | C8: 0.05
A9: Horizon (years, max 20) | B9: H | C9: 10
A10: Program length (years, fractional ok) | B10: L | C10: 1
A11: Tuition and fees, whole program ($) | B11: T | C11: 20000
A12: Scholarships and grants ($) | B12: Sch | C12: 0
A13: Part-time earnings while enrolled (pre-tax, $/yr) | B13: PT | C13: 0
A14: Extra living cost while enrolled ($/yr) | B14: Living | C14: 0
A15: Job search after program (months) | B15: gap | C15: 3
A16: Starting salary after program (pre-tax, $/yr) | B16: S1 | C16: 95000
... A20: Loan term (years) | B20: N | C20: 10
A22: DERIVED
A23: Annual loan payment P = B·r/(1−(1+r)^−N) | B23: P | C23: =IF($C$18=0,0,$C$18*$C$19/(1-(1+$C$19)^(-$C$20))) -> 2980.5898
A24: Salary start time ts = L + gap/12 (years from today) | B24: ts | C24: =$C$10+$C$15/12 -> 1.25
A25: First working year kf = FLOOR(ts)+1 | B25: kf | C25: =INT($C$24)+1 -> 2
A26: Net school cost per school-year = (T−Sch−B)/L + Living − PT·(1−t) | B26: C_sch | C26: =($C$11-$C$12-$C$18)/$C$10+$C$14-$C$13*(1-$C$7) -> 0
A28: Year k | B28: In horizon (k<=H) | C28: School fraction sf | D28: Working fraction wf | E28: Raise exponent | F28: Loan fraction lf | G28: CF_A keep working | H28: CF_B program | I28: Diff = CF_B − CF_A | J28: Cumulative diff | K28: Discount factor | L28: PV of diff | M28: S1 multiplier m(k) | N28: Payback helper
A29: 1 | B29: =IF(A29<=$C$9,1,0) -> 1 | C29: =MAX(0,MIN(1,$C$10-(A29-1))) -> 1 | D29: =MAX(0,MIN(1,A29-$C$24)) -> 0 | E29: =MAX(0,A29-$C$25) -> 0 | F29: =MAX(0,MIN(A29,$C$10+$C$20)-MAX(A29-1,$C$10)) -> 0 | G29: =$C$5*(1+$C$6)^(A29-1)*(1-$C$7) -> 45000 | H29: =-$C$26*C29+$C$16*(1+$C$17)^E29*(1-$C$7)*D29-$C$23*F29 -> 0 | I29: =H29-G29 -> -45000 | J29: =I29 -> -45000 | K29: =1/(1+$C$8)^A29 -> 0.95238095 | L29: =I29*K29*B29 -> -42857.143 | M29: =(1+$C$17)^E29*(1-$C$7)*D29*K29*B29 -> 0 | N29: =IF(AND(B29=1,COUNTIFS($A$29:$A$48,">="&A29,$B$29:$B$48,1,$J$29:$J$48,"<0")=0),A29,999) -> 999
A30: 2 | B30: =IF(A30<=$C$9,1,0) -> 1 | C30: =MAX(0,MIN(1,$C$10-(A30-1))) -> 0 | D30: =MAX(0,MIN(1,A30-$C$24)) -> 0.75 | E30: =MAX(0,A30-$C$25) -> 0 | F30: =MAX(0,MIN(A30,$C$10+$C$20)-MAX(A30-1,$C$10)) -> 1 | G30: =$C$5*(1+$C$6)^(A30-1)*(1-$C$7) -> 46350 | H30: =-$C$26*C30+$C$16*(1+$C$17)^E30*(1-$C$7)*D30-$C$23*F30 -> 50456.91 | I30: =H30-G30 -> 4106.9102 | J30: =J29+I30 -> -40893.09 | K30: =1/(1+$C$8)^A30 -> 0.90702948 | L30: =I30*K30*B30 -> 3725.0886 | M30: =(1+$C$17)^E30*(1-$C$7)*D30*K30*B30 -> 0.51020408 | N30: =IF(AND(B30=1,COUNTIFS($A$29:$A$48,">="&A30,$B$29:$B$48,1,$J$29:$J$48,"<0")=0),A30,999) -> 999
A31: 3 | B31: =IF(A31<=$C$9,1,0) -> 1 | C31: =MAX(0,MIN(1,$C$10-(A31-1))) -> 0 | D31: =MAX(0,MIN(1,A31-$C$24)) -> 1 | E31: =MAX(0,A31-$C$25) -> 1 | F31: =MAX(0,MIN(A31,$C$10+$C$20)-MAX(A31-1,$C$10)) -> 1 | G31: =$C$5*(1+$C$6)^(A31-1)*(1-$C$7) -> 47740.5 | H31: =-$C$26*C31+$C$16*(1+$C$17)^E31*(1-$C$7)*D31-$C$23*F31 -> 71119.41 | I31: =H31-G31 -> 23378.91 | J31: =J30+I31 -> -17514.18 | K31: =1/(1+$C$8)^A31 -> 0.8638376 | L31: =I31*K31*B31 -> 20195.582 | M31: =(1+$C$17)^E31*(1-$C$7)*D31*K31*B31 -> 0.67379333 | N31: =IF(AND(B31=1,COUNTIFS($A$29:$A$48,">="&A31,$B$29:$B$48,1,$J$29:$J$48,"<0")=0),A31,999) -> 999
A32: 4 | B32: =IF(A32<=$C$9,1,0) -> 1 | C32: =MAX(0,MIN(1,$C$10-(A32-1))) -> 0 | D32: =MAX(0,MIN(1,A32-$C$24)) -> 1 | E32: =MAX(0,A32-$C$25) -> 2 | F32: =MAX(0,MIN(A32,$C$10+$C$20)-MAX(A32-1,$C$10)) -> 1 | G32: =$C$5*(1+$C$6)^(A32-1)*(1-$C$7) -> 49172.715 | H32: =-$C$26*C32+$C$16*(1+$C$17)^E32*(1-$C$7)*D32-$C$23*F32 -> 74083.41 | I32: =H32-G32 -> 24910.695 | J32: =J31+I32 -> 7396.5157 | K32: =1/(1+$C$8)^A32 -> 0.82270247 | L32: =I32*K32*B32 -> 20494.091 | M32: =(1+$C$17)^E32*(1-$C$7)*D32*K32*B32 -> 0.66737625 | N32: =IF(AND(B32=1,COUNTIFS($A$29:$A$48,">="&A32,$B$29:$B$48,1,$J$29:$J$48,"<0")=0),A32,999) -> 4
A33: 5 | B33: =IF(A33<=$C$9,1,0) -> 1 | C33: =MAX(0,MIN(1,$C$10-(A33-1))) -> 0 | D33: =MAX(0,MIN(1,A33-$C$24)) -> 1 | E33: =MAX(0,A33-$C$25) -> 3 | F33: =MAX(0,MIN(A33,$C$10+$C$20)-MAX(A33-1,$C$10)) -> 1 | G33: =$C$5*(1+$C$6)^(A33-1)*(1-$C$7) -> 50647.896 | H33: =-$C$26*C33+$C$16*(1+$C$17)^E33*(1-$C$7)*D33-$C$23*F33 -> 77165.97 | I33: =H33-G33 -> 26518.074 | J33: =J32+I33 -> 33914.589 | K33: =1/(1+$C$8)^A33 -> 0.78352617 | L33: =I33*K33*B33 -> 20777.605 | M33: =(1+$C$17)^E33*(1-$C$7)*D33*K33*B33 -> 0.66102028 | N33: =IF(AND(B33=1,COUNTIFS($A$29:$A$48,">="&A33,$B$29:$B$48,1,$J$29:$J$48,"<0")=0),A33,999) -> 5
A34: 6 | B34: =IF(A34<=$C$9,1,0) -> 1 | C34: =MAX(0,MIN(1,$C$10-(A34-1))) -> 0 | D34: =MAX(0,MIN(1,A34-$C$24)) -> 1 | E34: =MAX(0,A34-$C$25) -> 4 | F34: =MAX(0,MIN(A34,$C$10+$C$20)-MAX(A34-1,$C$10)) -> 1 | G34: =$C$5*(1+$C$6)^(A34-1)*(1-$C$7) -> 52167.333 | H34: =-$C$26*C34+$C$16*(1+$C$17)^E34*(1-$C$7)*D34-$C$23*F34 -> 80371.833 | I34: =H34-G34 -> 28204.499 | J34: =J33+I34 -> 62119.089 | K34: =1/(1+$C$8)^A34 -> 0.7462154 | L34: =I34*K34*B34 -> 21046.632 | M34: =(1+$C$17)^E34*(1-$C$7)*D34*K34*B34 -> 0.65472485 | N34: =IF(AND(B34=1,COUNTIFS($A$29:$A$48,">="&A34,$B$29:$B$48,1,$J$29:$J$48,"<0")=0),A34,999) -> 6
A35: 7 | B35: =IF(A35<=$C$9,1,0) -> 1 | C35: =MAX(0,MIN(1,$C$10-(A35-1))) -> 0 | D35: =MAX(0,MIN(1,A35-$C$24)) -> 1 | E35: =MAX(0,A35-$C$25) -> 5 | F35: =MAX(0,MIN(A35,$C$10+$C$20)-MAX(A35-1,$C$10)) -> 1 | G35: =$C$5*(1+$C$6)^(A35-1)*(1-$C$7) -> 53732.353 | H35: =-$C$26*C35+$C$16*(1+$C$17)^E35*(1-$C$7)*D35-$C$23*F35 -> 83705.93 | I35: =H35-G35 -> 29973.576 | J35: =J34+I35 -> 92092.665 | K35: =1/(1+$C$8)^A35 -> 0.71068133 | L35: =I35*K35*B35 -> 21301.661 | M35: =(1+$C$17)^E35*(1-$C$7)*D35*K35*B35 -> 0.64848938 | N35: =IF(AND(B35=1,COUNTIFS($A$29:$A$48,">="&A35,$B$29:$B$48,1,$J$29:$J$48,"<0")=0),A35,999) -> 7
A36: 8 | B36: =IF(A36<=$C$9,1,0) -> 1 | C36: =MAX(0,MIN(1,$C$10-(A36-1))) -> 0 | D36: =MAX(0,MIN(1,A36-$C$24)) -> 1 | E36: =MAX(0,A36-$C$25) -> 6 | F36: =MAX(0,MIN(A36,$C$10+$C$20)-MAX(A36-1,$C$10)) -> 1 | G36: =$C$5*(1+$C$6)^(A36-1)*(1-$C$7) -> 55344.324 | H36: =-$C$26*C36+$C$16*(1+$C$17)^E36*(1-$C$7)*D36-$C$23*F36 -> 87173.39 | I36: =H36-G36 -> 31829.066 | J36: =J35+I36 -> 123921.73 | K36: =1/(1+$C$8)^A36 -> 0.67683936 | L36: =I36*K36*B36 -> 21543.165 | M36: =(1+$C$17)^E36*(1-$C$7)*D36*K36*B36 -> 0.64231329 | N36: =IF(AND(B36=1,COUNTIFS($A$29:$A$48,">="&A36,$B$29:$B$48,1,$J$29:$J$48,"<0")=0),A36,999) -> 8
A37: 9 | B37: =IF(A37<=$C$9,1,0) -> 1 | C37: =MAX(0,MIN(1,$C$10-(A37-1))) -> 0 | D37: =MAX(0,MIN(1,A37-$C$24)) -> 1 | E37: =MAX(0,A37-$C$25) -> 7 | F37: =MAX(0,MIN(A37,$C$10+$C$20)-MAX(A37-1,$C$10)) -> 1 | G37: =$C$5*(1+$C$6)^(A37-1)*(1-$C$7) -> 57004.654 | H37: =-$C$26*C37+$C$16*(1+$C$17)^E37*(1-$C$7)*D37-$C$23*F37 -> 90779.549 | I37: =H37-G37 -> 33774.896 | J37: =J36+I37 -> 157696.63 | K37: =1/(1+$C$8)^A37 -> 0.64460892 | L37: =I37*K37*B37 -> 21771.599 | M37: =(1+$C$17)^E37*(1-$C$7)*D37*K37*B37 -> 0.63619602 | N37: =IF(AND(B37=1,COUNTIFS($A$29:$A$48,">="&A37,$B$29:$B$48,1,$J$29:$J$48,"<0")=0),A37,999) -> 9
A38: 10 | B38: =IF(A38<=$C$9,1,0) -> 1 | C38: =MAX(0,MIN(1,$C$10-(A38-1))) -> 0 | D38: =MAX(0,MIN(1,A38-$C$24)) -> 1 | E38: =MAX(0,A38-$C$25) -> 8 | F38: =MAX(0,MIN(A38,$C$10+$C$20)-MAX(A38-1,$C$10)) -> 1 | G38: =$C$5*(1+$C$6)^(A38-1)*(1-$C$7) -> 58714.793 | H38: =-$C$26*C38+$C$16*(1+$C$17)^E38*(1-$C$7)*D38-$C$23*F38 -> 94529.955 | I38: =H38-G38 -> 35815.162 | J38: =J37+I38 -> 193511.79 | K38: =1/(1+$C$8)^A38 -> 0.61391325 | L38: =I38*K38*B38 -> 21987.403 | M38: =(1+$C$17)^E38*(1-$C$7)*D38*K38*B38 -> 0.63013701 | N38: =IF(AND(B38=1,COUNTIFS($A$29:$A$48,">="&A38,$B$29:$B$48,1,$J$29:$J$48,"<0")=0),A38,999) -> 10
A39: 11 | B39: =IF(A39<=$C$9,1,0) -> 0 | C39: =MAX(0,MIN(1,$C$10-(A39-1))) -> 0 | D39: =MAX(0,MIN(1,A39-$C$24)) -> 1 | E39: =MAX(0,A39-$C$25) -> 9 | F39: =MAX(0,MIN(A39,$C$10+$C$20)-MAX(A39-1,$C$10)) -> 1 | G39: =$C$5*(1+$C$6)^(A39-1)*(1-$C$7) -> 60476.237 | H39: =-$C$26*C39+$C$16*(1+$C$17)^E39*(1-$C$7)*D39-$C$23*F39 -> 98430.377 | I39: =H39-G39 -> 37954.14 | J39: =J38+I39 -> 231465.93 | K39: =1/(1+$C$8)^A39 -> 0.58467929 | L39: =I39*K39*B39 -> 0 | M39: =(1+$C$17)^E39*(1-$C$7)*D39*K39*B39 -> 0 | N39: =IF(AND(B39=1,COUNTIFS($A$29:$A$48,">="&A39,$B$29:$B$48,1,$J$29:$J$48,"<0")=0),A39,999) -> 999
A40: 12 | B40: =IF(A40<=$C$9,1,0) -> 0 | C40: =MAX(0,MIN(1,$C$10-(A40-1))) -> 0 | D40: =MAX(0,MIN(1,A40-$C$24)) -> 1 | E40: =MAX(0,A40-$C$25) -> 10 | F40: =MAX(0,MIN(A40,$C$10+$C$20)-MAX(A40-1,$C$10)) -> 0 | G40: =$C$5*(1+$C$6)^(A40-1)*(1-$C$7) -> 62290.524 | H40: =-$C$26*C40+$C$16*(1+$C$17)^E40*(1-$C$7)*D40-$C$23*F40 -> 105467.41 | I40: =H40-G40 -> 43176.881 | J40: =J39+I40 -> 274642.81 | K40: =1/(1+$C$8)^A40 -> 0.55683742 | L40: =I40*K40*B40 -> 0 | M40: =(1+$C$17)^E40*(1-$C$7)*D40*K40*B40 -> 0 | N40: =IF(AND(B40=1,COUNTIFS($A$29:$A$48,">="&A40,$B$29:$B$48,1,$J$29:$J$48,"<0")=0),A40,999) -> 999
A41: 13 | B41: =IF(A41<=$C$9,1,0) -> 0 | C41: =MAX(0,MIN(1,$C$10-(A41-1))) -> 0 | D41: =MAX(0,MIN(1,A41-$C$24)) -> 1 | E41: =MAX(0,A41-$C$25) -> 11 | F41: =MAX(0,MIN(A41,$C$10+$C$20)-MAX(A41-1,$C$10)) -> 0 | G41: =$C$5*(1+$C$6)^(A41-1)*(1-$C$7) -> 64159.24 | H41: =-$C$26*C41+$C$16*(1+$C$17)^E41*(1-$C$7)*D41-$C$23*F41 -> 109686.1 | I41: =H41-G41 -> 45526.862 | J41: =J40+I41 -> 320169.67 | K41: =1/(1+$C$8)^A41 -> 0.53032135 | L41: =I41*K41*B41 -> 0 | M41: =(1+$C$17)^E41*(1-$C$7)*D41*K41*B41 -> 0 | N41: =IF(AND(B41=1,COUNTIFS($A$29:$A$48,">="&A41,$B$29:$B$48,1,$J$29:$J$48,"<0")=0),A41,999) -> 999
... A48: 20 | B48: =IF(A48<=$C$9,1,0) -> 0 | C48: =MAX(0,MIN(1,$C$10-(A48-1))) -> 0 | D48: =MAX(0,MIN(1,A48-$C$24)) -> 1 | E48: =MAX(0,A48-$C$25) -> 18 | F48: =MAX(0,MIN(A48,$C$10+$C$20)-MAX(A48-1,$C$10)) -> 0 | G48: =$C$5*(1+$C$6)^(A48-1)*(1-$C$7) -> 78907.772 | H48: =-$C$26*C48+$C$16*(1+$C$17)^E48*(1-$C$7)*D48-$C$23*F48 -> 144339.43 | I48: =H48-G48 -> 65431.654 | J48: =J47+I48 -> 714789.84 | K48: =1/(1+$C$8)^A48 -> 0.37688948 | L48: =I48*K48*B48 -> 0 | M48: =(1+$C$17)^E48*(1-$C$7)*D48*K48*B48 -> 0 | N48: =IF(AND(B48=1,COUNTIFS($A$29:$A$48,">="&A48,$B$29:$B$48,1,$J$29:$J$48,"<0")=0),A48,999) -> 999
A50: OUTPUTS (check these by hand)
A51: Payback year (first k with cumulative diff ≥ 0 from k through H) | C51: =IF(MIN(N29:N48)=999,"Not within horizon",MIN(N29:N48)) -> 4
A52: NPV of (program − keep working), years 1..H ($) | C52: =SUM(L29:L48) -> 129985.68
A53: Σ S1 multiplier (NPV sensitivity to S1) | C53: =SUM(M29:M48) -> 5.7242545
...

Sheet Case2_ExpensiveSmallJump
A1: 2. Expensive program, small salary jump
A2: Expected behaviour: Does not pay back within 10 years; NPV negative; breakeven S1 well above 80k
A4: INPUTS (blue = hardcoded; edit these) | B4: Symbol
A5: Current salary (pre-tax, $/yr) | B5: S0 | C5: 70000
A6: Raise rate if you keep working | B6: g_work | C6: 0.03
A7: Effective tax rate (flat) | B7: t | C7: 0.25
A8: Discount rate | B8: d | C8: 0.05
A9: Horizon (years, max 20) | B9: H | C9: 10
A10: Program length (years, fractional ok) | B10: L | C10: 2
A11: Tuition and fees, whole program ($) | B11: T | C11: 120000
A12: Scholarships and grants ($) | B12: Sch | C12: 0
A13: Part-time earnings while enrolled (pre-tax, $/yr) | B13: PT | C13: 0
A14: Extra living cost while enrolled ($/yr) | B14: Living | C14: 0
A15: Job search after program (months) | B15: gap | C15: 3
A16: Starting salary after program (pre-tax, $/yr) | B16: S1 | C16: 80000
... A20: Loan term (years) | B20: N | C20: 10
A22: DERIVED
A23: Annual loan payment P = B·r/(1−(1+r)^−N) | B23: P | C23: =IF($C$18=0,0,$C$18*$C$19/(1-(1+$C$19)^(-$C$20))) -> 14902.949
A24: Salary start time ts = L + gap/12 (years from today) | B24: ts | C24: =$C$10+$C$15/12 -> 2.25
A25: First working year kf = FLOOR(ts)+1 | B25: kf | C25: =INT($C$24)+1 -> 3
A26: Net school cost per school-year = (T−Sch−B)/L + Living − PT·(1−t) | B26: C_sch | C26: =($C$11-$C$12-$C$18)/$C$10+$C$14-$C$13*(1-$C$7) -> 10000
A28: Year k | B28: In horizon (k<=H) | C28: School fraction sf | D28: Working fraction wf | E28: Raise exponent | F28: Loan fraction lf | G28: CF_A keep working | H28: CF_B program | I28: Diff = CF_B − CF_A | J28: Cumulative diff | K28: Discount factor | L28: PV of diff | M28: S1 multiplier m(k) | N28: Payback helper
A29: 1 | B29: =IF(A29<=$C$9,1,0) -> 1 | C29: =MAX(0,MIN(1,$C$10-(A29-1))) -> 1 | D29: =MAX(0,MIN(1,A29-$C$24)) -> 0 | E29: =MAX(0,A29-$C$25) -> 0 | F29: =MAX(0,MIN(A29,$C$10+$C$20)-MAX(A29-1,$C$10)) -> 0 | G29: =$C$5*(1+$C$6)^(A29-1)*(1-$C$7) -> 52500 | H29: =-$C$26*C29+$C$16*(1+$C$17)^E29*(1-$C$7)*D29-$C$23*F29 -> -10000 | I29: =H29-G29 -> -62500 | J29: =I29 -> -62500 | K29: =1/(1+$C$8)^A29 -> 0.95238095 | L29: =I29*K29*B29 -> -59523.81 | M29: =(1+$C$17)^E29*(1-$C$7)*D29*K29*B29 -> 0 | N29: =IF(AND(B29=1,COUNTIFS($A$29:$A$48,">="&A29,$B$29:$B$48,1,$J$29:$J$48,"<0")=0),A29,999) -> 999
A30: 2 | B30: =IF(A30<=$C$9,1,0) -> 1 | C30: =MAX(0,MIN(1,$C$10-(A30-1))) -> 1 | D30: =MAX(0,MIN(1,A30-$C$24)) -> 0 | E30: =MAX(0,A30-$C$25) -> 0 | F30: =MAX(0,MIN(A30,$C$10+$C$20)-MAX(A30-1,$C$10)) -> 0 | G30: =$C$5*(1+$C$6)^(A30-1)*(1-$C$7) -> 54075 | H30: =-$C$26*C30+$C$16*(1+$C$17)^E30*(1-$C$7)*D30-$C$23*F30 -> -10000 | I30: =H30-G30 -> -64075 | J30: =J29+I30 -> -126575 | K30: =1/(1+$C$8)^A30 -> 0.90702948 | L30: =I30*K30*B30 -> -58117.914 | M30: =(1+$C$17)^E30*(1-$C$7)*D30*K30*B30 -> 0 | N30: =IF(AND(B30=1,COUNTIFS($A$29:$A$48,">="&A30,$B$29:$B$48,1,$J$29:$J$48,"<0")=0),A30,999) -> 999
A31: 3 | B31: =IF(A31<=$C$9,1,0) -> 1 | C31: =MAX(0,MIN(1,$C$10-(A31-1))) -> 0 | D31: =MAX(0,MIN(1,A31-$C$24)) -> 0.75 | E31: =MAX(0,A31-$C$25) -> 0 | F31: =MAX(0,MIN(A31,$C$10+$C$20)-MAX(A31-1,$C$10)) -> 1 | G31: =$C$5*(1+$C$6)^(A31-1)*(1-$C$7) -> 55697.25 | H31: =-$C$26*C31+$C$16*(1+$C$17)^E31*(1-$C$7)*D31-$C$23*F31 -> 30097.051 | I31: =H31-G31 -> -25600.199 | J31: =J30+I31 -> -152175.2 | K31: =1/(1+$C$8)^A31 -> 0.8638376 | L31: =I31*K31*B31 -> -22114.414 | M31: =(1+$C$17)^E31*(1-$C$7)*D31*K31*B31 -> 0.48590865 | N31: =IF(AND(B31=1,COUNTIFS($A$29:$A$48,">="&A31,$B$29:$B$48,1,$J$29:$J$48,"<0")=0),A31,999) -> 999
A32: 4 | B32: =IF(A32<=$C$9,1,0) -> 1 | C32: =MAX(0,MIN(1,$C$10-(A32-1))) -> 0 | D32: =MAX(0,MIN(1,A32-$C$24)) -> 1 | E32: =MAX(0,A32-$C$25) -> 1 | F32: =MAX(0,MIN(A32,$C$10+$C$20)-MAX(A32-1,$C$10)) -> 1 | G32: =$C$5*(1+$C$6)^(A32-1)*(1-$C$7) -> 57368.167 | H32: =-$C$26*C32+$C$16*(1+$C$17)^E32*(1-$C$7)*D32-$C$23*F32 -> 47497.051 | I32: =H32-G32 -> -9871.1164 | J32: =J31+I32 -> -162046.32 | K32: =1/(1+$C$8)^A32 -> 0.82270247 | L32: =I32*K32*B32 -> -8120.9919 | M32: =(1+$C$17)^E32*(1-$C$7)*D32*K32*B32 -> 0.64170793 | N32: =IF(AND(B32=1,COUNTIFS($A$29:$A$48,">="&A32,$B$29:$B$48,1,$J$29:$J$48,"<0")=0),A32,999) -> 999
A33: 5 | B33: =IF(A33<=$C$9,1,0) -> 1 | C33: =MAX(0,MIN(1,$C$10-(A33-1))) -> 0 | D33: =MAX(0,MIN(1,A33-$C$24)) -> 1 | E33: =MAX(0,A33-$C$25) -> 2 | F33: =MAX(0,MIN(A33,$C$10+$C$20)-MAX(A33-1,$C$10)) -> 1 | G33: =$C$5*(1+$C$6)^(A33-1)*(1-$C$7) -> 59089.213 | H33: =-$C$26*C33+$C$16*(1+$C$17)^E33*(1-$C$7)*D33-$C$23*F33 -> 49993.051 | I33: =H33-G33 -> -9096.1614 | J33: =J32+I33 -> -171142.48 | K33: =1/(1+$C$8)^A33 -> 0.78352617 | L33: =I33*K33*B33 -> -7127.0805 | M33: =(1+$C$17)^E33*(1-$C$7)*D33*K33*B33 -> 0.63559643 | N33: =IF(AND(B33=1,COUNTIFS($A$29:$A$48,">="&A33,$B$29:$B$48,1,$J$29:$J$48,"<0")=0),A33,999) -> 999
A34: 6 | B34: =IF(A34<=$C$9,1,0) -> 1 | C34: =MAX(0,MIN(1,$C$10-(A34-1))) -> 0 | D34: =MAX(0,MIN(1,A34-$C$24)) -> 1 | E34: =MAX(0,A34-$C$25) -> 3 | F34: =MAX(0,MIN(A34,$C$10+$C$20)-MAX(A34-1,$C$10)) -> 1 | G34: =$C$5*(1+$C$6)^(A34-1)*(1-$C$7) -> 60861.889 | H34: =-$C$26*C34+$C$16*(1+$C$17)^E34*(1-$C$7)*D34-$C$23*F34 -> 52588.891 | I34: =H34-G34 -> -8272.9978 | J34: =J33+I34 -> -179415.47 | K34: =1/(1+$C$8)^A34 -> 0.7462154 | L34: =I34*K34*B34 -> -6173.4383 | M34: =(1+$C$17)^E34*(1-$C$7)*D34*K34*B34 -> 0.62954313 | N34: =IF(AND(B34=1,COUNTIFS($A$29:$A$48,">="&A34,$B$29:$B$48,1,$J$29:$J$48,"<0")=0),A34,999) -> 999
A35: 7 | B35: =IF(A35<=$C$9,1,0) -> 1 | C35: =MAX(0,MIN(1,$C$10-(A35-1))) -> 0 | D35: =MAX(0,MIN(1,A35-$C$24)) -> 1 | E35: =MAX(0,A35-$C$25) -> 4 | F35: =MAX(0,MIN(A35,$C$10+$C$20)-MAX(A35-1,$C$10)) -> 1 | G35: =$C$5*(1+$C$6)^(A35-1)*(1-$C$7) -> 62687.746 | H35: =-$C$26*C35+$C$16*(1+$C$17)^E35*(1-$C$7)*D35-$C$23*F35 -> 55288.565 | I35: =H35-G35 -> -7399.1808 | J35: =J34+I35 -> -186814.66 | K35: =1/(1+$C$8)^A35 -> 0.71068133 | L35: =I35*K35*B35 -> -5258.4597 | M35: =(1+$C$17)^E35*(1-$C$7)*D35*K35*B35 -> 0.62354748 | N35: =IF(AND(B35=1,COUNTIFS($A$29:$A$48,">="&A35,$B$29:$B$48,1,$J$29:$J$48,"<0")=0),A35,999) -> 999
A36: 8 | B36: =IF(A36<=$C$9,1,0) -> 1 | C36: =MAX(0,MIN(1,$C$10-(A36-1))) -> 0 | D36: =MAX(0,MIN(1,A36-$C$24)) -> 1 | E36: =MAX(0,A36-$C$25) -> 5 | F36: =MAX(0,MIN(A36,$C$10+$C$20)-MAX(A36-1,$C$10)) -> 1 | G36: =$C$5*(1+$C$6)^(A36-1)*(1-$C$7) -> 64568.378 | H36: =-$C$26*C36+$C$16*(1+$C$17)^E36*(1-$C$7)*D36-$C$23*F36 -> 58096.225 | I36: =H36-G36 -> -6472.1527 | J36: =J35+I36 -> -193286.81 | K36: =1/(1+$C$8)^A36 -> 0.67683936 | L36: =I36*K36*B36 -> -4380.6077 | M36: =(1+$C$17)^E36*(1-$C$7)*D36*K36*B36 -> 0.61760893 | N36: =IF(AND(B36=1,COUNTIFS($A$29:$A$48,">="&A36,$B$29:$B$48,1,$J$29:$J$48,"<0")=0),A36,999) -> 999
A37: 9 | B37: =IF(A37<=$C$9,1,0) -> 1 | C37: =MAX(0,MIN(1,$C$10-(A37-1))) -> 0 | D37: =MAX(0,MIN(1,A37-$C$24)) -> 1 | E37: =MAX(0,A37-$C$25) -> 6 | F37: =MAX(0,MIN(A37,$C$10+$C$20)-MAX(A37-1,$C$10)) -> 1 | G37: =$C$5*(1+$C$6)^(A37-1)*(1-$C$7) -> 66505.429 | H37: =-$C$26*C37+$C$16*(1+$C$17)^E37*(1-$C$7)*D37-$C$23*F37 -> 61016.192 | I37: =H37-G37 -> -5489.237 | J37: =J36+I37 -> -198776.04 | K37: =1/(1+$C$8)^A37 -> 0.64460892 | L37: =I37*K37*B37 -> -3538.4111 | M37: =(1+$C$17)^E37*(1-$C$7)*D37*K37*B37 -> 0.61172694 | N37: =IF(AND(B37=1,COUNTIFS($A$29:$A$48,">="&A37,$B$29:$B$48,1,$J$29:$J$48,"<0")=0),A37,999) -> 999
A38: 10 | B38: =IF(A38<=$C$9,1,0) -> 1 | C38: =MAX(0,MIN(1,$C$10-(A38-1))) -> 0 | D38: =MAX(0,MIN(1,A38-$C$24)) -> 1 | E38: =MAX(0,A38-$C$25) -> 7 | F38: =MAX(0,MIN(A38,$C$10+$C$20)-MAX(A38-1,$C$10)) -> 1 | G38: =$C$5*(1+$C$6)^(A38-1)*(1-$C$7) -> 68500.592 | H38: =-$C$26*C38+$C$16*(1+$C$17)^E38*(1-$C$7)*D38-$C$23*F38 -> 64052.958 | I38: =H38-G38 -> -4447.6343 | J38: =J37+I38 -> -203223.68 | K38: =1/(1+$C$8)^A38 -> 0.61391325 | L38: =I38*K38*B38 -> -2730.4616 | M38: =(1+$C$17)^E38*(1-$C$7)*D38*K38*B38 -> 0.60590097 | N38: =IF(AND(B38=1,COUNTIFS($A$29:$A$48,">="&A38,$B$29:$B$48,1,$J$29:$J$48,"<0")=0),A38,999) -> 999
A39: 11 | B39: =IF(A39<=$C$9,1,0) -> 0 | C39: =MAX(0,MIN(1,$C$10-(A39-1))) -> 0 | D39: =MAX(0,MIN(1,A39-$C$24)) -> 1 | E39: =MAX(0,A39-$C$25) -> 8 | F39: =MAX(0,MIN(A39,$C$10+$C$20)-MAX(A39-1,$C$10)) -> 1 | G39: =$C$5*(1+$C$6)^(A39-1)*(1-$C$7) -> 70555.61 | H39: =-$C$26*C39+$C$16*(1+$C$17)^E39*(1-$C$7)*D39-$C$23*F39 -> 67211.194 | I39: =H39-G39 -> -3344.4158 | J39: =J38+I39 -> -206568.09 | K39: =1/(1+$C$8)^A39 -> 0.58467929 | L39: =I39*K39*B39 -> 0 | M39: =(1+$C$17)^E39*(1-$C$7)*D39*K39*B39 -> 0 | N39: =IF(AND(B39=1,COUNTIFS($A$29:$A$48,">="&A39,$B$29:$B$48,1,$J$29:$J$48,"<0")=0),A39,999) -> 999
A40: 12 | B40: =IF(A40<=$C$9,1,0) -> 0 | C40: =MAX(0,MIN(1,$C$10-(A40-1))) -> 0 | D40: =MAX(0,MIN(1,A40-$C$24)) -> 1 | E40: =MAX(0,A40-$C$25) -> 9 | F40: =MAX(0,MIN(A40,$C$10+$C$20)-MAX(A40-1,$C$10)) -> 1 | G40: =$C$5*(1+$C$6)^(A40-1)*(1-$C$7) -> 72672.278 | H40: =-$C$26*C40+$C$16*(1+$C$17)^E40*(1-$C$7)*D40-$C$23*F40 -> 70495.76 | I40: =H40-G40 -> -2176.5183 | J40: =J39+I40 -> -208744.61 | K40: =1/(1+$C$8)^A40 -> 0.55683742 | L40: =I40*K40*B40 -> 0 | M40: =(1+$C$17)^E40*(1-$C$7)*D40*K40*B40 -> 0 | N40: =IF(AND(B40=1,COUNTIFS($A$29:$A$48,">="&A40,$B$29:$B$48,1,$J$29:$J$48,"<0")=0),A40,999) -> 999
A41: 13 | B41: =IF(A41<=$C$9,1,0) -> 0 | C41: =MAX(0,MIN(1,$C$10-(A41-1))) -> 0 | D41: =MAX(0,MIN(1,A41-$C$24)) -> 1 | E41: =MAX(0,A41-$C$25) -> 10 | F41: =MAX(0,MIN(A41,$C$10+$C$20)-MAX(A41-1,$C$10)) -> 0 | G41: =$C$5*(1+$C$6)^(A41-1)*(1-$C$7) -> 74852.447 | H41: =-$C$26*C41+$C$16*(1+$C$17)^E41*(1-$C$7)*D41-$C$23*F41 -> 88814.657 | I41: =H41-G41 -> 13962.211 | J41: =J40+I41 -> -194782.4 | K41: =1/(1+$C$8)^A41 -> 0.53032135 | L41: =I41*K41*B41 -> 0 | M41: =(1+$C$17)^E41*(1-$C$7)*D41*K41*B41 -> 0 | N41: =IF(AND(B41=1,COUNTIFS($A$29:$A$48,">="&A41,$B$29:$B$48,1,$J$29:$J$48,"<0")=0),A41,999) -> 999
... A48: 20 | B48: =IF(A48<=$C$9,1,0) -> 0 | C48: =MAX(0,MIN(1,$C$10-(A48-1))) -> 0 | D48: =MAX(0,MIN(1,A48-$C$24)) -> 1 | E48: =MAX(0,A48-$C$25) -> 17 | F48: =MAX(0,MIN(A48,$C$10+$C$20)-MAX(A48-1,$C$10)) -> 0 | G48: =$C$5*(1+$C$6)^(A48-1)*(1-$C$7) -> 92059.068 | H48: =-$C$26*C48+$C$16*(1+$C$17)^E48*(1-$C$7)*D48-$C$23*F48 -> 116874.03 | I48: =H48-G48 -> 24814.962 | J48: =J47+I48 -> -55999.376 | K48: =1/(1+$C$8)^A48 -> 0.37688948 | L48: =I48*K48*B48 -> 0 | M48: =(1+$C$17)^E48*(1-$C$7)*D48*K48*B48 -> 0 | N48: =IF(AND(B48=1,COUNTIFS($A$29:$A$48,">="&A48,$B$29:$B$48,1,$J$29:$J$48,"<0")=0),A48,999) -> 999
A50: OUTPUTS (check these by hand)
A51: Payback year (first k with cumulative diff ≥ 0 from k through H) | C51: =IF(MIN(N29:N48)=999,"Not within horizon",MIN(N29:N48)) -> Not within horizon
A52: NPV of (program − keep working), years 1..H ($) | C52: =SUM(L29:L48) -> -177085.59
A53: Σ S1 multiplier (NPV sensitivity to S1) | C53: =SUM(M29:M48) -> 4.8515405
...

Sheet Case3_MSBA_Fractional
A1: 3. Ten-month program (MSBA-like), Scorecard salary
A2: Expected behaviour: Fractional year and mid-year salary start prorate correctly. With S0 = 65k, the Scorecard 1-yr median (73k) is not enough: no payback in 10 yrs, breakeven S1 ≈ 79k
A4: INPUTS (blue = hardcoded; edit these) | B4: Symbol
A5: Current salary (pre-tax, $/yr) | B5: S0 | C5: 65000
A6: Raise rate if you keep working | B6: g_work | C6: 0.03
A7: Effective tax rate (flat) | B7: t | C7: 0.25
A8: Discount rate | B8: d | C8: 0.05
A9: Horizon (years, max 20) | B9: H | C9: 10
A10: Program length (years, fractional ok) | B10: L | C10: 0.83
A11: Tuition and fees, whole program ($) | B11: T | C11: 40000
A12: Scholarships and grants ($) | B12: Sch | C12: 5000
A13: Part-time earnings while enrolled (pre-tax, $/yr) | B13: PT | C13: 0
A14: Extra living cost while enrolled ($/yr) | B14: Living | C14: 0
A15: Job search after program (months) | B15: gap | C15: 3
A16: Starting salary after program (pre-tax, $/yr) | B16: S1 | C16: 73268
... A20: Loan term (years) | B20: N | C20: 10
A22: DERIVED
A23: Annual loan payment P = B·r/(1−(1+r)^−N) | B23: P | C23: =IF($C$18=0,0,$C$18*$C$19/(1-(1+$C$19)^(-$C$20))) -> 5216.0321
A24: Salary start time ts = L + gap/12 (years from today) | B24: ts | C24: =$C$10+$C$15/12 -> 1.08
A25: First working year kf = FLOOR(ts)+1 | B25: kf | C25: =INT($C$24)+1 -> 2
A26: Net school cost per school-year = (T−Sch−B)/L + Living − PT·(1−t) | B26: C_sch | C26: =($C$11-$C$12-$C$18)/$C$10+$C$14-$C$13*(1-$C$7) -> 0
A28: Year k | B28: In horizon (k<=H) | C28: School fraction sf | D28: Working fraction wf | E28: Raise exponent | F28: Loan fraction lf | G28: CF_A keep working | H28: CF_B program | I28: Diff = CF_B − CF_A | J28: Cumulative diff | K28: Discount factor | L28: PV of diff | M28: S1 multiplier m(k) | N28: Payback helper
A29: 1 | B29: =IF(A29<=$C$9,1,0) -> 1 | C29: =MAX(0,MIN(1,$C$10-(A29-1))) -> 0.83 | D29: =MAX(0,MIN(1,A29-$C$24)) -> 0 | E29: =MAX(0,A29-$C$25) -> 0 | F29: =MAX(0,MIN(A29,$C$10+$C$20)-MAX(A29-1,$C$10)) -> 0.17 | G29: =$C$5*(1+$C$6)^(A29-1)*(1-$C$7) -> 48750 | H29: =-$C$26*C29+$C$16*(1+$C$17)^E29*(1-$C$7)*D29-$C$23*F29 -> -886.72546 | I29: =H29-G29 -> -49636.725 | J29: =I29 -> -49636.725 | K29: =1/(1+$C$8)^A29 -> 0.95238095 | L29: =I29*K29*B29 -> -47273.072 | M29: =(1+$C$17)^E29*(1-$C$7)*D29*K29*B29 -> 0 | N29: =IF(AND(B29=1,COUNTIFS($A$29:$A$48,">="&A29,$B$29:$B$48,1,$J$29:$J$48,"<0")=0),A29,999) -> 999
A30: 2 | B30: =IF(A30<=$C$9,1,0) -> 1 | C30: =MAX(0,MIN(1,$C$10-(A30-1))) -> 0 | D30: =MAX(0,MIN(1,A30-$C$24)) -> 0.92 | E30: =MAX(0,A30-$C$25) -> 0 | F30: =MAX(0,MIN(A30,$C$10+$C$20)-MAX(A30-1,$C$10)) -> 1 | G30: =$C$5*(1+$C$6)^(A30-1)*(1-$C$7) -> 50212.5 | H30: =-$C$26*C30+$C$16*(1+$C$17)^E30*(1-$C$7)*D30-$C$23*F30 -> 45338.888 | I30: =H30-G30 -> -4873.6121 | J30: =J29+I30 -> -54510.338 | K30: =1/(1+$C$8)^A30 -> 0.90702948 | L30: =I30*K30*B30 -> -4420.5098 | M30: =(1+$C$17)^E30*(1-$C$7)*D30*K30*B30 -> 0.62585034 | N30: =IF(AND(B30=1,COUNTIFS($A$29:$A$48,">="&A30,$B$29:$B$48,1,$J$29:$J$48,"<0")=0),A30,999) -> 999
A31: 3 | B31: =IF(A31<=$C$9,1,0) -> 1 | C31: =MAX(0,MIN(1,$C$10-(A31-1))) -> 0 | D31: =MAX(0,MIN(1,A31-$C$24)) -> 1 | E31: =MAX(0,A31-$C$25) -> 1 | F31: =MAX(0,MIN(A31,$C$10+$C$20)-MAX(A31-1,$C$10)) -> 1 | G31: =$C$5*(1+$C$6)^(A31-1)*(1-$C$7) -> 51718.875 | H31: =-$C$26*C31+$C$16*(1+$C$17)^E31*(1-$C$7)*D31-$C$23*F31 -> 51933.008 | I31: =H31-G31 -> 214.1329 | J31: =J30+I31 -> -54296.205 | K31: =1/(1+$C$8)^A31 -> 0.8638376 | L31: =I31*K31*B31 -> 184.97605 | M31: =(1+$C$17)^E31*(1-$C$7)*D31*K31*B31 -> 0.67379333 | N31: =IF(AND(B31=1,COUNTIFS($A$29:$A$48,">="&A31,$B$29:$B$48,1,$J$29:$J$48,"<0")=0),A31,999) -> 999
A32: 4 | B32: =IF(A32<=$C$9,1,0) -> 1 | C32: =MAX(0,MIN(1,$C$10-(A32-1))) -> 0 | D32: =MAX(0,MIN(1,A32-$C$24)) -> 1 | E32: =MAX(0,A32-$C$25) -> 2 | F32: =MAX(0,MIN(A32,$C$10+$C$20)-MAX(A32-1,$C$10)) -> 1 | G32: =$C$5*(1+$C$6)^(A32-1)*(1-$C$7) -> 53270.441 | H32: =-$C$26*C32+$C$16*(1+$C$17)^E32*(1-$C$7)*D32-$C$23*F32 -> 54218.969 | I32: =H32-G32 -> 948.52825 | J32: =J31+I32 -> -53347.676 | K32: =1/(1+$C$8)^A32 -> 0.82270247 | L32: =I32*K32*B32 -> 780.35654 | M32: =(1+$C$17)^E32*(1-$C$7)*D32*K32*B32 -> 0.66737625 | N32: =IF(AND(B32=1,COUNTIFS($A$29:$A$48,">="&A32,$B$29:$B$48,1,$J$29:$J$48,"<0")=0),A32,999) -> 999
A33: 5 | B33: =IF(A33<=$C$9,1,0) -> 1 | C33: =MAX(0,MIN(1,$C$10-(A33-1))) -> 0 | D33: =MAX(0,MIN(1,A33-$C$24)) -> 1 | E33: =MAX(0,A33-$C$25) -> 3 | F33: =MAX(0,MIN(A33,$C$10+$C$20)-MAX(A33-1,$C$10)) -> 1 | G33: =$C$5*(1+$C$6)^(A33-1)*(1-$C$7) -> 54868.554 | H33: =-$C$26*C33+$C$16*(1+$C$17)^E33*(1-$C$7)*D33-$C$23*F33 -> 56596.37 | I33: =H33-G33 -> 1727.8151 | J33: =J32+I33 -> -51619.861 | K33: =1/(1+$C$8)^A33 -> 0.78352617 | L33: =I33*K33*B33 -> 1353.7883 | M33: =(1+$C$17)^E33*(1-$C$7)*D33*K33*B33 -> 0.66102028 | N33: =IF(AND(B33=1,COUNTIFS($A$29:$A$48,">="&A33,$B$29:$B$48,1,$J$29:$J$48,"<0")=0),A33,999) -> 999
A34: 6 | B34: =IF(A34<=$C$9,1,0) -> 1 | C34: =MAX(0,MIN(1,$C$10-(A34-1))) -> 0 | D34: =MAX(0,MIN(1,A34-$C$24)) -> 1 | E34: =MAX(0,A34-$C$25) -> 4 | F34: =MAX(0,MIN(A34,$C$10+$C$20)-MAX(A34-1,$C$10)) -> 1 | G34: =$C$5*(1+$C$6)^(A34-1)*(1-$C$7) -> 56514.611 | H34: =-$C$26*C34+$C$16*(1+$C$17)^E34*(1-$C$7)*D34-$C$23*F34 -> 59068.866 | I34: =H34-G34 -> 2554.2545 | J34: =J33+I34 -> -49065.607 | K34: =1/(1+$C$8)^A34 -> 0.7462154 | L34: =I34*K34*B34 -> 1906.024 | M34: =(1+$C$17)^E34*(1-$C$7)*D34*K34*B34 -> 0.65472485 | N34: =IF(AND(B34=1,COUNTIFS($A$29:$A$48,">="&A34,$B$29:$B$48,1,$J$29:$J$48,"<0")=0),A34,999) -> 999
A35: 7 | B35: =IF(A35<=$C$9,1,0) -> 1 | C35: =MAX(0,MIN(1,$C$10-(A35-1))) -> 0 | D35: =MAX(0,MIN(1,A35-$C$24)) -> 1 | E35: =MAX(0,A35-$C$25) -> 5 | F35: =MAX(0,MIN(A35,$C$10+$C$20)-MAX(A35-1,$C$10)) -> 1 | G35: =$C$5*(1+$C$6)^(A35-1)*(1-$C$7) -> 58210.049 | H35: =-$C$26*C35+$C$16*(1+$C$17)^E35*(1-$C$7)*D35-$C$23*F35 -> 61640.262 | I35: =H35-G35 -> 3430.2121 | J35: =J34+I35 -> -45635.395 | K35: =1/(1+$C$8)^A35 -> 0.71068133 | L35: =I35*K35*B35 -> 2437.7877 | M35: =(1+$C$17)^E35*(1-$C$7)*D35*K35*B35 -> 0.64848938 | N35: =IF(AND(B35=1,COUNTIFS($A$29:$A$48,">="&A35,$B$29:$B$48,1,$J$29:$J$48,"<0")=0),A35,999) -> 999
A36: 8 | B36: =IF(A36<=$C$9,1,0) -> 1 | C36: =MAX(0,MIN(1,$C$10-(A36-1))) -> 0 | D36: =MAX(0,MIN(1,A36-$C$24)) -> 1 | E36: =MAX(0,A36-$C$25) -> 6 | F36: =MAX(0,MIN(A36,$C$10+$C$20)-MAX(A36-1,$C$10)) -> 1 | G36: =$C$5*(1+$C$6)^(A36-1)*(1-$C$7) -> 59956.351 | H36: =-$C$26*C36+$C$16*(1+$C$17)^E36*(1-$C$7)*D36-$C$23*F36 -> 64314.513 | I36: =H36-G36 -> 4358.1623 | J36: =J35+I36 -> -41277.232 | K36: =1/(1+$C$8)^A36 -> 0.67683936 | L36: =I36*K36*B36 -> 2949.7758 | M36: =(1+$C$17)^E36*(1-$C$7)*D36*K36*B36 -> 0.64231329 | N36: =IF(AND(B36=1,COUNTIFS($A$29:$A$48,">="&A36,$B$29:$B$48,1,$J$29:$J$48,"<0")=0),A36,999) -> 999
A37: 9 | B37: =IF(A37<=$C$9,1,0) -> 1 | C37: =MAX(0,MIN(1,$C$10-(A37-1))) -> 0 | D37: =MAX(0,MIN(1,A37-$C$24)) -> 1 | E37: =MAX(0,A37-$C$25) -> 7 | F37: =MAX(0,MIN(A37,$C$10+$C$20)-MAX(A37-1,$C$10)) -> 1 | G37: =$C$5*(1+$C$6)^(A37-1)*(1-$C$7) -> 61755.041 | H37: =-$C$26*C37+$C$16*(1+$C$17)^E37*(1-$C$7)*D37-$C$23*F37 -> 67095.735 | I37: =H37-G37 -> 5340.6936 | J37: =J36+I37 -> -35936.539 | K37: =1/(1+$C$8)^A37 -> 0.64460892 | L37: =I37*K37*B37 -> 3442.6587 | M37: =(1+$C$17)^E37*(1-$C$7)*D37*K37*B37 -> 0.63619602 | N37: =IF(AND(B37=1,COUNTIFS($A$29:$A$48,">="&A37,$B$29:$B$48,1,$J$29:$J$48,"<0")=0),A37,999) -> 999
A38: 10 | B38: =IF(A38<=$C$9,1,0) -> 1 | C38: =MAX(0,MIN(1,$C$10-(A38-1))) -> 0 | D38: =MAX(0,MIN(1,A38-$C$24)) -> 1 | E38: =MAX(0,A38-$C$25) -> 8 | F38: =MAX(0,MIN(A38,$C$10+$C$20)-MAX(A38-1,$C$10)) -> 1 | G38: =$C$5*(1+$C$6)^(A38-1)*(1-$C$7) -> 63607.693 | H38: =-$C$26*C38+$C$16*(1+$C$17)^E38*(1-$C$7)*D38-$C$23*F38 -> 69988.206 | I38: =H38-G38 -> 6380.5131 | J38: =J37+I38 -> -29556.026 | K38: =1/(1+$C$8)^A38 -> 0.61391325 | L38: =I38*K38*B38 -> 3917.0815 | M38: =(1+$C$17)^E38*(1-$C$7)*D38*K38*B38 -> 0.63013701 | N38: =IF(AND(B38=1,COUNTIFS($A$29:$A$48,">="&A38,$B$29:$B$48,1,$J$29:$J$48,"<0")=0),A38,999) -> 999
A39: 11 | B39: =IF(A39<=$C$9,1,0) -> 0 | C39: =MAX(0,MIN(1,$C$10-(A39-1))) -> 0 | D39: =MAX(0,MIN(1,A39-$C$24)) -> 1 | E39: =MAX(0,A39-$C$25) -> 9 | F39: =MAX(0,MIN(A39,$C$10+$C$20)-MAX(A39-1,$C$10)) -> 0.83 | G39: =$C$5*(1+$C$6)^(A39-1)*(1-$C$7) -> 65515.923 | H39: =-$C$26*C39+$C$16*(1+$C$17)^E39*(1-$C$7)*D39-$C$23*F39 -> 73883.101 | I39: =H39-G39 -> 8367.1773 | J39: =J38+I39 -> -21188.848 | K39: =1/(1+$C$8)^A39 -> 0.58467929 | L39: =I39*K39*B39 -> 0 | M39: =(1+$C$17)^E39*(1-$C$7)*D39*K39*B39 -> 0 | N39: =IF(AND(B39=1,COUNTIFS($A$29:$A$48,">="&A39,$B$29:$B$48,1,$J$29:$J$48,"<0")=0),A39,999) -> 999
A40: 12 | B40: =IF(A40<=$C$9,1,0) -> 0 | C40: =MAX(0,MIN(1,$C$10-(A40-1))) -> 0 | D40: =MAX(0,MIN(1,A40-$C$24)) -> 1 | E40: =MAX(0,A40-$C$25) -> 10 | F40: =MAX(0,MIN(A40,$C$10+$C$20)-MAX(A40-1,$C$10)) -> 0 | G40: =$C$5*(1+$C$6)^(A40-1)*(1-$C$7) -> 67481.401 | H40: =-$C$26*C40+$C$16*(1+$C$17)^E40*(1-$C$7)*D40-$C$23*F40 -> 81340.904 | I40: =H40-G40 -> 13859.503 | J40: =J39+I40 -> -7329.346 | K40: =1/(1+$C$8)^A40 -> 0.55683742 | L40: =I40*K40*B40 -> 0 | M40: =(1+$C$17)^E40*(1-$C$7)*D40*K40*B40 -> 0 | N40: =IF(AND(B40=1,COUNTIFS($A$29:$A$48,">="&A40,$B$29:$B$48,1,$J$29:$J$48,"<0")=0),A40,999) -> 999
A41: 13 | B41: =IF(A41<=$C$9,1,0) -> 0 | C41: =MAX(0,MIN(1,$C$10-(A41-1))) -> 0 | D41: =MAX(0,MIN(1,A41-$C$24)) -> 1 | E41: =MAX(0,A41-$C$25) -> 11 | F41: =MAX(0,MIN(A41,$C$10+$C$20)-MAX(A41-1,$C$10)) -> 0 | G41: =$C$5*(1+$C$6)^(A41-1)*(1-$C$7) -> 69505.843 | H41: =-$C$26*C41+$C$16*(1+$C$17)^E41*(1-$C$7)*D41-$C$23*F41 -> 84594.54 | I41: =H41-G41 -> 15088.697 | J41: =J40+I41 -> 7759.3507 | K41: =1/(1+$C$8)^A41 -> 0.53032135 | L41: =I41*K41*B41 -> 0 | M41: =(1+$C$17)^E41*(1-$C$7)*D41*K41*B41 -> 0 | N41: =IF(AND(B41=1,COUNTIFS($A$29:$A$48,">="&A41,$B$29:$B$48,1,$J$29:$J$48,"<0")=0),A41,999) -> 999
... A48: 20 | B48: =IF(A48<=$C$9,1,0) -> 0 | C48: =MAX(0,MIN(1,$C$10-(A48-1))) -> 0 | D48: =MAX(0,MIN(1,A48-$C$24)) -> 1 | E48: =MAX(0,A48-$C$25) -> 18 | F48: =MAX(0,MIN(A48,$C$10+$C$20)-MAX(A48-1,$C$10)) -> 0 | G48: =$C$5*(1+$C$6)^(A48-1)*(1-$C$7) -> 85483.42 | H48: =-$C$26*C48+$C$16*(1+$C$17)^E48*(1-$C$7)*D48-$C$23*F48 -> 111320.64 | I48: =H48-G48 -> 25837.223 | J48: =J47+I48 -> 154074.57 | K48: =1/(1+$C$8)^A48 -> 0.37688948 | L48: =I48*K48*B48 -> 0 | M48: =(1+$C$17)^E48*(1-$C$7)*D48*K48*B48 -> 0 | N48: =IF(AND(B48=1,COUNTIFS($A$29:$A$48,">="&A48,$B$29:$B$48,1,$J$29:$J$48,"<0")=0),A48,999) -> 999
A50: OUTPUTS (check these by hand)
A51: Payback year (first k with cumulative diff ≥ 0 from k through H) | C51: =IF(MIN(N29:N48)=999,"Not within horizon",MIN(N29:N48)) -> Not within horizon
A52: NPV of (program − keep working), years 1..H ($) | C52: =SUM(L29:L48) -> -34721.133
A53: Σ S1 multiplier (NPV sensitivity to S1) | C53: =SUM(M29:M48) -> 5.8399007
...

Sheet Case4_NoLoans
A1: 4. No borrowing (paid from savings)
A2: Expected behaviour: Loan payment P = 0; full net tuition (20k) hits year 1; pays back around year 6
A4: INPUTS (blue = hardcoded; edit these) | B4: Symbol
A5: Current salary (pre-tax, $/yr) | B5: S0 | C5: 55000
A6: Raise rate if you keep working | B6: g_work | C6: 0.03
A7: Effective tax rate (flat) | B7: t | C7: 0.25
A8: Discount rate | B8: d | C8: 0.05
A9: Horizon (years, max 20) | B9: H | C9: 10
A10: Program length (years, fractional ok) | B10: L | C10: 1
A11: Tuition and fees, whole program ($) | B11: T | C11: 30000
A12: Scholarships and grants ($) | B12: Sch | C12: 10000
A13: Part-time earnings while enrolled (pre-tax, $/yr) | B13: PT | C13: 0
A14: Extra living cost while enrolled ($/yr) | B14: Living | C14: 0
A15: Job search after program (months) | B15: gap | C15: 3
A16: Starting salary after program (pre-tax, $/yr) | B16: S1 | C16: 75000
... A20: Loan term (years) | B20: N | C20: 10
A22: DERIVED
A23: Annual loan payment P = B·r/(1−(1+r)^−N) | B23: P | C23: =IF($C$18=0,0,$C$18*$C$19/(1-(1+$C$19)^(-$C$20))) -> 0
A24: Salary start time ts = L + gap/12 (years from today) | B24: ts | C24: =$C$10+$C$15/12 -> 1.25
A25: First working year kf = FLOOR(ts)+1 | B25: kf | C25: =INT($C$24)+1 -> 2
A26: Net school cost per school-year = (T−Sch−B)/L + Living − PT·(1−t) | B26: C_sch | C26: =($C$11-$C$12-$C$18)/$C$10+$C$14-$C$13*(1-$C$7) -> 20000
A28: Year k | B28: In horizon (k<=H) | C28: School fraction sf | D28: Working fraction wf | E28: Raise exponent | F28: Loan fraction lf | G28: CF_A keep working | H28: CF_B program | I28: Diff = CF_B − CF_A | J28: Cumulative diff | K28: Discount factor | L28: PV of diff | M28: S1 multiplier m(k) | N28: Payback helper
A29: 1 | B29: =IF(A29<=$C$9,1,0) -> 1 | C29: =MAX(0,MIN(1,$C$10-(A29-1))) -> 1 | D29: =MAX(0,MIN(1,A29-$C$24)) -> 0 | E29: =MAX(0,A29-$C$25) -> 0 | F29: =MAX(0,MIN(A29,$C$10+$C$20)-MAX(A29-1,$C$10)) -> 0 | G29: =$C$5*(1+$C$6)^(A29-1)*(1-$C$7) -> 41250 | H29: =-$C$26*C29+$C$16*(1+$C$17)^E29*(1-$C$7)*D29-$C$23*F29 -> -20000 | I29: =H29-G29 -> -61250 | J29: =I29 -> -61250 | K29: =1/(1+$C$8)^A29 -> 0.95238095 | L29: =I29*K29*B29 -> -58333.333 | M29: =(1+$C$17)^E29*(1-$C$7)*D29*K29*B29 -> 0 | N29: =IF(AND(B29=1,COUNTIFS($A$29:$A$48,">="&A29,$B$29:$B$48,1,$J$29:$J$48,"<0")=0),A29,999) -> 999
A30: 2 | B30: =IF(A30<=$C$9,1,0) -> 1 | C30: =MAX(0,MIN(1,$C$10-(A30-1))) -> 0 | D30: =MAX(0,MIN(1,A30-$C$24)) -> 0.75 | E30: =MAX(0,A30-$C$25) -> 0 | F30: =MAX(0,MIN(A30,$C$10+$C$20)-MAX(A30-1,$C$10)) -> 1 | G30: =$C$5*(1+$C$6)^(A30-1)*(1-$C$7) -> 42487.5 | H30: =-$C$26*C30+$C$16*(1+$C$17)^E30*(1-$C$7)*D30-$C$23*F30 -> 42187.5 | I30: =H30-G30 -> -300 | J30: =J29+I30 -> -61550 | K30: =1/(1+$C$8)^A30 -> 0.90702948 | L30: =I30*K30*B30 -> -272.10884 | M30: =(1+$C$17)^E30*(1-$C$7)*D30*K30*B30 -> 0.51020408 | N30: =IF(AND(B30=1,COUNTIFS($A$29:$A$48,">="&A30,$B$29:$B$48,1,$J$29:$J$48,"<0")=0),A30,999) -> 999
A31: 3 | B31: =IF(A31<=$C$9,1,0) -> 1 | C31: =MAX(0,MIN(1,$C$10-(A31-1))) -> 0 | D31: =MAX(0,MIN(1,A31-$C$24)) -> 1 | E31: =MAX(0,A31-$C$25) -> 1 | F31: =MAX(0,MIN(A31,$C$10+$C$20)-MAX(A31-1,$C$10)) -> 1 | G31: =$C$5*(1+$C$6)^(A31-1)*(1-$C$7) -> 43762.125 | H31: =-$C$26*C31+$C$16*(1+$C$17)^E31*(1-$C$7)*D31-$C$23*F31 -> 58500 | I31: =H31-G31 -> 14737.875 | J31: =J30+I31 -> -46812.125 | K31: =1/(1+$C$8)^A31 -> 0.8638376 | L31: =I31*K31*B31 -> 12731.131 | M31: =(1+$C$17)^E31*(1-$C$7)*D31*K31*B31 -> 0.67379333 | N31: =IF(AND(B31=1,COUNTIFS($A$29:$A$48,">="&A31,$B$29:$B$48,1,$J$29:$J$48,"<0")=0),A31,999) -> 999
A32: 4 | B32: =IF(A32<=$C$9,1,0) -> 1 | C32: =MAX(0,MIN(1,$C$10-(A32-1))) -> 0 | D32: =MAX(0,MIN(1,A32-$C$24)) -> 1 | E32: =MAX(0,A32-$C$25) -> 2 | F32: =MAX(0,MIN(A32,$C$10+$C$20)-MAX(A32-1,$C$10)) -> 1 | G32: =$C$5*(1+$C$6)^(A32-1)*(1-$C$7) -> 45074.989 | H32: =-$C$26*C32+$C$16*(1+$C$17)^E32*(1-$C$7)*D32-$C$23*F32 -> 60840 | I32: =H32-G32 -> 15765.011 | J32: =J31+I32 -> -31047.114 | K32: =1/(1+$C$8)^A32 -> 0.82270247 | L32: =I32*K32*B32 -> 12969.914 | M32: =(1+$C$17)^E32*(1-$C$7)*D32*K32*B32 -> 0.66737625 | N32: =IF(AND(B32=1,COUNTIFS($A$29:$A$48,">="&A32,$B$29:$B$48,1,$J$29:$J$48,"<0")=0),A32,999) -> 999
A33: 5 | B33: =IF(A33<=$C$9,1,0) -> 1 | C33: =MAX(0,MIN(1,$C$10-(A33-1))) -> 0 | D33: =MAX(0,MIN(1,A33-$C$24)) -> 1 | E33: =MAX(0,A33-$C$25) -> 3 | F33: =MAX(0,MIN(A33,$C$10+$C$20)-MAX(A33-1,$C$10)) -> 1 | G33: =$C$5*(1+$C$6)^(A33-1)*(1-$C$7) -> 46427.238 | H33: =-$C$26*C33+$C$16*(1+$C$17)^E33*(1-$C$7)*D33-$C$23*F33 -> 63273.6 | I33: =H33-G33 -> 16846.362 | J33: =J32+I33 -> -14200.752 | K33: =1/(1+$C$8)^A33 -> 0.78352617 | L33: =I33*K33*B33 -> 13199.565 | M33: =(1+$C$17)^E33*(1-$C$7)*D33*K33*B33 -> 0.66102028 | N33: =IF(AND(B33=1,COUNTIFS($A$29:$A$48,">="&A33,$B$29:$B$48,1,$J$29:$J$48,"<0")=0),A33,999) -> 999
A34: 6 | B34: =IF(A34<=$C$9,1,0) -> 1 | C34: =MAX(0,MIN(1,$C$10-(A34-1))) -> 0 | D34: =MAX(0,MIN(1,A34-$C$24)) -> 1 | E34: =MAX(0,A34-$C$25) -> 4 | F34: =MAX(0,MIN(A34,$C$10+$C$20)-MAX(A34-1,$C$10)) -> 1 | G34: =$C$5*(1+$C$6)^(A34-1)*(1-$C$7) -> 47820.056 | H34: =-$C$26*C34+$C$16*(1+$C$17)^E34*(1-$C$7)*D34-$C$23*F34 -> 65804.544 | I34: =H34-G34 -> 17984.488 | J34: =J33+I34 -> 3783.7363 | K34: =1/(1+$C$8)^A34 -> 0.7462154 | L34: =I34*K34*B34 -> 13420.302 | M34: =(1+$C$17)^E34*(1-$C$7)*D34*K34*B34 -> 0.65472485 | N34: =IF(AND(B34=1,COUNTIFS($A$29:$A$48,">="&A34,$B$29:$B$48,1,$J$29:$J$48,"<0")=0),A34,999) -> 6
A35: 7 | B35: =IF(A35<=$C$9,1,0) -> 1 | C35: =MAX(0,MIN(1,$C$10-(A35-1))) -> 0 | D35: =MAX(0,MIN(1,A35-$C$24)) -> 1 | E35: =MAX(0,A35-$C$25) -> 5 | F35: =MAX(0,MIN(A35,$C$10+$C$20)-MAX(A35-1,$C$10)) -> 1 | G35: =$C$5*(1+$C$6)^(A35-1)*(1-$C$7) -> 49254.657 | H35: =-$C$26*C35+$C$16*(1+$C$17)^E35*(1-$C$7)*D35-$C$23*F35 -> 68436.726 | I35: =H35-G35 -> 19182.069 | J35: =J34+I35 -> 22965.805 | K35: =1/(1+$C$8)^A35 -> 0.71068133 | L35: =I35*K35*B35 -> 13632.338 | M35: =(1+$C$17)^E35*(1-$C$7)*D35*K35*B35 -> 0.64848938 | N35: =IF(AND(B35=1,COUNTIFS($A$29:$A$48,">="&A35,$B$29:$B$48,1,$J$29:$J$48,"<0")=0),A35,999) -> 7
A36: 8 | B36: =IF(A36<=$C$9,1,0) -> 1 | C36: =MAX(0,MIN(1,$C$10-(A36-1))) -> 0 | D36: =MAX(0,MIN(1,A36-$C$24)) -> 1 | E36: =MAX(0,A36-$C$25) -> 6 | F36: =MAX(0,MIN(A36,$C$10+$C$20)-MAX(A36-1,$C$10)) -> 1 | G36: =$C$5*(1+$C$6)^(A36-1)*(1-$C$7) -> 50732.297 | H36: =-$C$26*C36+$C$16*(1+$C$17)^E36*(1-$C$7)*D36-$C$23*F36 -> 71174.195 | I36: =H36-G36 -> 20441.898 | J36: =J35+I36 -> 43407.703 | K36: =1/(1+$C$8)^A36 -> 0.67683936 | L36: =I36*K36*B36 -> 13835.881 | M36: =(1+$C$17)^E36*(1-$C$7)*D36*K36*B36 -> 0.64231329 | N36: =IF(AND(B36=1,COUNTIFS($A$29:$A$48,">="&A36,$B$29:$B$48,1,$J$29:$J$48,"<0")=0),A36,999) -> 8
A37: 9 | B37: =IF(A37<=$C$9,1,0) -> 1 | C37: =MAX(0,MIN(1,$C$10-(A37-1))) -> 0 | D37: =MAX(0,MIN(1,A37-$C$24)) -> 1 | E37: =MAX(0,A37-$C$25) -> 7 | F37: =MAX(0,MIN(A37,$C$10+$C$20)-MAX(A37-1,$C$10)) -> 1 | G37: =$C$5*(1+$C$6)^(A37-1)*(1-$C$7) -> 52254.266 | H37: =-$C$26*C37+$C$16*(1+$C$17)^E37*(1-$C$7)*D37-$C$23*F37 -> 74021.163 | I37: =H37-G37 -> 21766.897 | J37: =J36+I37 -> 65174.599 | K37: =1/(1+$C$8)^A37 -> 0.64460892 | L37: =I37*K37*B37 -> 14031.136 | M37: =(1+$C$17)^E37*(1-$C$7)*D37*K37*B37 -> 0.63619602 | N37: =IF(AND(B37=1,COUNTIFS($A$29:$A$48,">="&A37,$B$29:$B$48,1,$J$29:$J$48,"<0")=0),A37,999) -> 9
A38: 10 | B38: =IF(A38<=$C$9,1,0) -> 1 | C38: =MAX(0,MIN(1,$C$10-(A38-1))) -> 0 | D38: =MAX(0,MIN(1,A38-$C$24)) -> 1 | E38: =MAX(0,A38-$C$25) -> 8 | F38: =MAX(0,MIN(A38,$C$10+$C$20)-MAX(A38-1,$C$10)) -> 1 | G38: =$C$5*(1+$C$6)^(A38-1)*(1-$C$7) -> 53821.894 | H38: =-$C$26*C38+$C$16*(1+$C$17)^E38*(1-$C$7)*D38-$C$23*F38 -> 76982.009 | I38: =H38-G38 -> 23160.115 | J38: =J37+I38 -> 88334.715 | K38: =1/(1+$C$8)^A38 -> 0.61391325 | L38: =I38*K38*B38 -> 14218.302 | M38: =(1+$C$17)^E38*(1-$C$7)*D38*K38*B38 -> 0.63013701 | N38: =IF(AND(B38=1,COUNTIFS($A$29:$A$48,">="&A38,$B$29:$B$48,1,$J$29:$J$48,"<0")=0),A38,999) -> 10
A39: 11 | B39: =IF(A39<=$C$9,1,0) -> 0 | C39: =MAX(0,MIN(1,$C$10-(A39-1))) -> 0 | D39: =MAX(0,MIN(1,A39-$C$24)) -> 1 | E39: =MAX(0,A39-$C$25) -> 9 | F39: =MAX(0,MIN(A39,$C$10+$C$20)-MAX(A39-1,$C$10)) -> 1 | G39: =$C$5*(1+$C$6)^(A39-1)*(1-$C$7) -> 55436.551 | H39: =-$C$26*C39+$C$16*(1+$C$17)^E39*(1-$C$7)*D39-$C$23*F39 -> 80061.289 | I39: =H39-G39 -> 24624.739 | J39: =J38+I39 -> 112959.45 | K39: =1/(1+$C$8)^A39 -> 0.58467929 | L39: =I39*K39*B39 -> 0 | M39: =(1+$C$17)^E39*(1-$C$7)*D39*K39*B39 -> 0 | N39: =IF(AND(B39=1,COUNTIFS($A$29:$A$48,">="&A39,$B$29:$B$48,1,$J$29:$J$48,"<0")=0),A39,999) -> 999
A40: 12 | B40: =IF(A40<=$C$9,1,0) -> 0 | C40: =MAX(0,MIN(1,$C$10-(A40-1))) -> 0 | D40: =MAX(0,MIN(1,A40-$C$24)) -> 1 | E40: =MAX(0,A40-$C$25) -> 10 | F40: =MAX(0,MIN(A40,$C$10+$C$20)-MAX(A40-1,$C$10)) -> 0 | G40: =$C$5*(1+$C$6)^(A40-1)*(1-$C$7) -> 57099.647 | H40: =-$C$26*C40+$C$16*(1+$C$17)^E40*(1-$C$7)*D40-$C$23*F40 -> 83263.741 | I40: =H40-G40 -> 26164.094 | J40: =J39+I40 -> 139123.55 | K40: =1/(1+$C$8)^A40 -> 0.55683742 | L40: =I40*K40*B40 -> 0 | M40: =(1+$C$17)^E40*(1-$C$7)*D40*K40*B40 -> 0 | N40: =IF(AND(B40=1,COUNTIFS($A$29:$A$48,">="&A40,$B$29:$B$48,1,$J$29:$J$48,"<0")=0),A40,999) -> 999
A41: 13 | B41: =IF(A41<=$C$9,1,0) -> 0 | C41: =MAX(0,MIN(1,$C$10-(A41-1))) -> 0 | D41: =MAX(0,MIN(1,A41-$C$24)) -> 1 | E41: =MAX(0,A41-$C$25) -> 11 | F41: =MAX(0,MIN(A41,$C$10+$C$20)-MAX(A41-1,$C$10)) -> 0 | G41: =$C$5*(1+$C$6)^(A41-1)*(1-$C$7) -> 58812.637 | H41: =-$C$26*C41+$C$16*(1+$C$17)^E41*(1-$C$7)*D41-$C$23*F41 -> 86594.291 | I41: =H41-G41 -> 27781.654 | J41: =J40+I41 -> 166905.2 | K41: =1/(1+$C$8)^A41 -> 0.53032135 | L41: =I41*K41*B41 -> 0 | M41: =(1+$C$17)^E41*(1-$C$7)*D41*K41*B41 -> 0 | N41: =IF(AND(B41=1,COUNTIFS($A$29:$A$48,">="&A41,$B$29:$B$48,1,$J$29:$J$48,"<0")=0),A41,999) -> 999
... A48: 20 | B48: =IF(A48<=$C$9,1,0) -> 0 | C48: =MAX(0,MIN(1,$C$10-(A48-1))) -> 0 | D48: =MAX(0,MIN(1,A48-$C$24)) -> 1 | E48: =MAX(0,A48-$C$25) -> 18 | F48: =MAX(0,MIN(A48,$C$10+$C$20)-MAX(A48-1,$C$10)) -> 0 | G48: =$C$5*(1+$C$6)^(A48-1)*(1-$C$7) -> 72332.125 | H48: =-$C$26*C48+$C$16*(1+$C$17)^E48*(1-$C$7)*D48-$C$23*F48 -> 113952.18 | I48: =H48-G48 -> 41620.054 | J48: =J47+I48 -> 414041.21 | K48: =1/(1+$C$8)^A48 -> 0.37688948 | L48: =I48*K48*B48 -> 0 | M48: =(1+$C$17)^E48*(1-$C$7)*D48*K48*B48 -> 0 | N48: =IF(AND(B48=1,COUNTIFS($A$29:$A$48,">="&A48,$B$29:$B$48,1,$J$29:$J$48,"<0")=0),A48,999) -> 999
A50: OUTPUTS (check these by hand)
A51: Payback year (first k with cumulative diff ≥ 0 from k through H) | C51: =IF(MIN(N29:N48)=999,"Not within horizon",MIN(N29:N48)) -> 6
A52: NPV of (program − keep working), years 1..H ($) | C52: =SUM(L29:L48) -> 49433.126
A53: Σ S1 multiplier (NPV sensitivity to S1) | C53: =SUM(M29:M48) -> 5.7242545
...

Sheet Case5_NeverPaysOff
A1: 5. High salary already, program never pays off
A2: Expected behaviour: Never pays back; NPV strongly negative; breakeven S1 far above 92k
A4: INPUTS (blue = hardcoded; edit these) | B4: Symbol
A5: Current salary (pre-tax, $/yr) | B5: S0 | C5: 90000
A6: Raise rate if you keep working | B6: g_work | C6: 0.03
A7: Effective tax rate (flat) | B7: t | C7: 0.25
A8: Discount rate | B8: d | C8: 0.05
A9: Horizon (years, max 20) | B9: H | C9: 10
A10: Program length (years, fractional ok) | B10: L | C10: 2
A11: Tuition and fees, whole program ($) | B11: T | C11: 90000
A12: Scholarships and grants ($) | B12: Sch | C12: 0
A13: Part-time earnings while enrolled (pre-tax, $/yr) | B13: PT | C13: 0
A14: Extra living cost while enrolled ($/yr) | B14: Living | C14: 0
A15: Job search after program (months) | B15: gap | C15: 3
A16: Starting salary after program (pre-tax, $/yr) | B16: S1 | C16: 92000
... A20: Loan term (years) | B20: N | C20: 10
A22: DERIVED
A23: Annual loan payment P = B·r/(1−(1+r)^−N) | B23: P | C23: =IF($C$18=0,0,$C$18*$C$19/(1-(1+$C$19)^(-$C$20))) -> 13412.654
A24: Salary start time ts = L + gap/12 (years from today) | B24: ts | C24: =$C$10+$C$15/12 -> 2.25
A25: First working year kf = FLOOR(ts)+1 | B25: kf | C25: =INT($C$24)+1 -> 3
A26: Net school cost per school-year = (T−Sch−B)/L + Living − PT·(1−t) | B26: C_sch | C26: =($C$11-$C$12-$C$18)/$C$10+$C$14-$C$13*(1-$C$7) -> 0
A28: Year k | B28: In horizon (k<=H) | C28: School fraction sf | D28: Working fraction wf | E28: Raise exponent | F28: Loan fraction lf | G28: CF_A keep working | H28: CF_B program | I28: Diff = CF_B − CF_A | J28: Cumulative diff | K28: Discount factor | L28: PV of diff | M28: S1 multiplier m(k) | N28: Payback helper
A29: 1 | B29: =IF(A29<=$C$9,1,0) -> 1 | C29: =MAX(0,MIN(1,$C$10-(A29-1))) -> 1 | D29: =MAX(0,MIN(1,A29-$C$24)) -> 0 | E29: =MAX(0,A29-$C$25) -> 0 | F29: =MAX(0,MIN(A29,$C$10+$C$20)-MAX(A29-1,$C$10)) -> 0 | G29: =$C$5*(1+$C$6)^(A29-1)*(1-$C$7) -> 67500 | H29: =-$C$26*C29+$C$16*(1+$C$17)^E29*(1-$C$7)*D29-$C$23*F29 -> 0 | I29: =H29-G29 -> -67500 | J29: =I29 -> -67500 | K29: =1/(1+$C$8)^A29 -> 0.95238095 | L29: =I29*K29*B29 -> -64285.714 | M29: =(1+$C$17)^E29*(1-$C$7)*D29*K29*B29 -> 0 | N29: =IF(AND(B29=1,COUNTIFS($A$29:$A$48,">="&A29,$B$29:$B$48,1,$J$29:$J$48,"<0")=0),A29,999) -> 999
A30: 2 | B30: =IF(A30<=$C$9,1,0) -> 1 | C30: =MAX(0,MIN(1,$C$10-(A30-1))) -> 1 | D30: =MAX(0,MIN(1,A30-$C$24)) -> 0 | E30: =MAX(0,A30-$C$25) -> 0 | F30: =MAX(0,MIN(A30,$C$10+$C$20)-MAX(A30-1,$C$10)) -> 0 | G30: =$C$5*(1+$C$6)^(A30-1)*(1-$C$7) -> 69525 | H30: =-$C$26*C30+$C$16*(1+$C$17)^E30*(1-$C$7)*D30-$C$23*F30 -> 0 | I30: =H30-G30 -> -69525 | J30: =J29+I30 -> -137025 | K30: =1/(1+$C$8)^A30 -> 0.90702948 | L30: =I30*K30*B30 -> -63061.224 | M30: =(1+$C$17)^E30*(1-$C$7)*D30*K30*B30 -> 0 | N30: =IF(AND(B30=1,COUNTIFS($A$29:$A$48,">="&A30,$B$29:$B$48,1,$J$29:$J$48,"<0")=0),A30,999) -> 999
A31: 3 | B31: =IF(A31<=$C$9,1,0) -> 1 | C31: =MAX(0,MIN(1,$C$10-(A31-1))) -> 0 | D31: =MAX(0,MIN(1,A31-$C$24)) -> 0.75 | E31: =MAX(0,A31-$C$25) -> 0 | F31: =MAX(0,MIN(A31,$C$10+$C$20)-MAX(A31-1,$C$10)) -> 1 | G31: =$C$5*(1+$C$6)^(A31-1)*(1-$C$7) -> 71610.75 | H31: =-$C$26*C31+$C$16*(1+$C$17)^E31*(1-$C$7)*D31-$C$23*F31 -> 38337.346 | I31: =H31-G31 -> -33273.404 | J31: =J30+I31 -> -170298.4 | K31: =1/(1+$C$8)^A31 -> 0.8638376 | L31: =I31*K31*B31 -> -28742.817 | M31: =(1+$C$17)^E31*(1-$C$7)*D31*K31*B31 -> 0.48590865 | N31: =IF(AND(B31=1,COUNTIFS($A$29:$A$48,">="&A31,$B$29:$B$48,1,$J$29:$J$48,"<0")=0),A31,999) -> 999
A32: 4 | B32: =IF(A32<=$C$9,1,0) -> 1 | C32: =MAX(0,MIN(1,$C$10-(A32-1))) -> 0 | D32: =MAX(0,MIN(1,A32-$C$24)) -> 1 | E32: =MAX(0,A32-$C$25) -> 1 | F32: =MAX(0,MIN(A32,$C$10+$C$20)-MAX(A32-1,$C$10)) -> 1 | G32: =$C$5*(1+$C$6)^(A32-1)*(1-$C$7) -> 73759.073 | H32: =-$C$26*C32+$C$16*(1+$C$17)^E32*(1-$C$7)*D32-$C$23*F32 -> 58347.346 | I32: =H32-G32 -> -15411.726 | J32: =J31+I32 -> -185710.13 | K32: =1/(1+$C$8)^A32 -> 0.82270247 | L32: =I32*K32*B32 -> -12679.266 | M32: =(1+$C$17)^E32*(1-$C$7)*D32*K32*B32 -> 0.64170793 | N32: =IF(AND(B32=1,COUNTIFS($A$29:$A$48,">="&A32,$B$29:$B$48,1,$J$29:$J$48,"<0")=0),A32,999) -> 999
A33: 5 | B33: =IF(A33<=$C$9,1,0) -> 1 | C33: =MAX(0,MIN(1,$C$10-(A33-1))) -> 0 | D33: =MAX(0,MIN(1,A33-$C$24)) -> 1 | E33: =MAX(0,A33-$C$25) -> 2 | F33: =MAX(0,MIN(A33,$C$10+$C$20)-MAX(A33-1,$C$10)) -> 1 | G33: =$C$5*(1+$C$6)^(A33-1)*(1-$C$7) -> 75971.845 | H33: =-$C$26*C33+$C$16*(1+$C$17)^E33*(1-$C$7)*D33-$C$23*F33 -> 61217.746 | I33: =H33-G33 -> -14754.099 | J33: =J32+I33 -> -200464.23 | K33: =1/(1+$C$8)^A33 -> 0.78352617 | L33: =I33*K33*B33 -> -11560.222 | M33: =(1+$C$17)^E33*(1-$C$7)*D33*K33*B33 -> 0.63559643 | N33: =IF(AND(B33=1,COUNTIFS($A$29:$A$48,">="&A33,$B$29:$B$48,1,$J$29:$J$48,"<0")=0),A33,999) -> 999
A34: 6 | B34: =IF(A34<=$C$9,1,0) -> 1 | C34: =MAX(0,MIN(1,$C$10-(A34-1))) -> 0 | D34: =MAX(0,MIN(1,A34-$C$24)) -> 1 | E34: =MAX(0,A34-$C$25) -> 3 | F34: =MAX(0,MIN(A34,$C$10+$C$20)-MAX(A34-1,$C$10)) -> 1 | G34: =$C$5*(1+$C$6)^(A34-1)*(1-$C$7) -> 78251 | H34: =-$C$26*C34+$C$16*(1+$C$17)^E34*(1-$C$7)*D34-$C$23*F34 -> 64202.962 | I34: =H34-G34 -> -14048.038 | J34: =J33+I34 -> -214512.27 | K34: =1/(1+$C$8)^A34 -> 0.7462154 | L34: =I34*K34*B34 -> -10482.862 | M34: =(1+$C$17)^E34*(1-$C$7)*D34*K34*B34 -> 0.62954313 | N34: =IF(AND(B34=1,COUNTIFS($A$29:$A$48,">="&A34,$B$29:$B$48,1,$J$29:$J$48,"<0")=0),A34,999) -> 999
